const fnWIthError = () => {
    throw new Error('Some error')
}

fnWIthError()

console.log('Continue...')

// Создаем ошибку Uncaught